Workbook

Sheet Ordre_Execution
A1: Plateforme de Données Intelligente et Évolutive — Backlog & ordre d'exécution
A2: Statuts et modèles sont lus en direct depuis les feuilles de phase. Colonne « Gate utilisateur » : à passer à Oui uniquement par validation de phase.
A4: Phase | B4: Feuille | C4: Intitulé | D4: Objectif | E4: Modèle dominant | F4: Nb tâches | G4: Non fait | H4: En cours | I4: À valider | J4: Validé | K4: % validé | L4: Gate utilisateur | M4: Livrable portfolio
A5: P0 | B5: P0_Fondations | C5: Fondations & environnement Claude Code | D5: Repo propre, outillage, CI, Docker local, graphify, ADR d'architecture. | E5: Haiku/Sonnet | F5: =COUNTA(P0_Fondations!$A$2:$A$200) -> 7 | G5: =COUNTIF(P0_Fondations!$L$2:$L$200,"Non fait") -> 7 | H5: =COUNTIF(P0_Fondations!$L$2:$L$200,"En cours") -> 0 | I5: =COUNTIF(P0_Fondations!$L$2:$L$200,"À valider") -> 0 | J5: =COUNTIF(P0_Fondations!$L$2:$L$200,"Validé") -> 0 | K5: =IF(F5=0,0,J5/F5) -> 0 | L5: Non | M5: Repo GitHub pro avec CI verte et ADR
A6: P1 | B6: P1_Ingestion_Bronze | C6: Ingestion & couche Bronze | D6: Connecteurs multi-sources, écriture Bronze immuable, rejets, simulateur de dérive. | E6: Sonnet | F6: =COUNTA(P1_Ingestion_Bronze!$A$2:$A$200) -> 9 | G6: =COUNTIF(P1_Ingestion_Bronze!$L$2:$L$200,"Non fait") -> 9 | H6: =COUNTIF(P1_Ingestion_Bronze!$L$2:$L$200,"En cours") -> 0 | I6: =COUNTIF(P1_Ingestion_Bronze!$L$2:$L$200,"À valider") -> 0 | J6: =COUNTIF(P1_Ingestion_Bronze!$L$2:$L$200,"Validé") -> 0 | K6: =IF(F6=0,0,J6/F6) -> 0 | L6: Non | M6: Connecteurs + Bronze rejouable
A7: P2 | B7: P2_Schema_Evolution | C7: Détection de schéma & gestion des évolutions | D7: Registry versionné, diff de schémas, classification d'impact, politique d'évolution. | E7: Opus/Sonnet | F7: =COUNTA(P2_Schema_Evolution!$A$2:$A$200) -> 7 | G7: =COUNTIF(P2_Schema_Evolution!$L$2:$L$200,"Non fait") -> 7 | H7: =COUNTIF(P2_Schema_Evolution!$L$2:$L$200,"En cours") -> 0 | I7: =COUNTIF(P2_Schema_Evolution!$L$2:$L$200,"À valider") -> 0 | J7: =COUNTIF(P2_Schema_Evolution!$L$2:$L$200,"Validé") -> 0 | K7: =IF(F7=0,0,J7/F7) -> 0 | L7: Non | M7: Moteur de schema evolution (différenciant CV)
A8: P3 | B8: P3_Mapping_Silver | C8: Auto-mapping adaptatif & couche Silver | D8: Mapping règles + LLM/RAG, revue humaine, transformations sûres, nettoyage, dédup, Silver. | E8: Opus/Sonnet | F8: =COUNTA(P3_Mapping_Silver!$A$2:$A$200) -> 9 | G8: =COUNTIF(P3_Mapping_Silver!$L$2:$L$200,"Non fait") -> 9 | H8: =COUNTIF(P3_Mapping_Silver!$L$2:$L$200,"En cours") -> 0 | I8: =COUNTIF(P3_Mapping_Silver!$L$2:$L$200,"À valider") -> 0 | J8: =COUNTIF(P3_Mapping_Silver!$L$2:$L$200,"Validé") -> 0 | K8: =IF(F8=0,0,J8/F8) -> 0 | L8: Non | M8: Auto-mapping évalué (précision/rappel)
A9: P4 | B9: P4_Qualite_Quarantaine | C9: Qualité des données & quarantaine | D9: Règles qualité, anomalies, scores, quarantaine dynamique, validation Silver→Gold. | E9: Sonnet/Opus | F9: =COUNTA(P4_Qualite_Quarantaine!$A$2:$A$200) -> 7 | G9: =COUNTIF(P4_Qualite_Quarantaine!$L$2:$L$200,"Non fait") -> 7 | H9: =COUNTIF(P4_Qualite_Quarantaine!$L$2:$L$200,"En cours") -> 0 | I9: =COUNTIF(P4_Qualite_Quarantaine!$L$2:$L$200,"À valider") -> 0 | J9: =COUNTIF(P4_Qualite_Quarantaine!$L$2:$L$200,"Validé") -> 0 | K9: =IF(F9=0,0,J9/F9) -> 0 | L9: Non | M9: Data quality framework + rapports
A10: P5 | B10: P5_Gold_API_UI | C10: Gold, data products, API & interface | D10: Data products avec contrat BIA, vues DuckDB, API FastAPI, catalogue, dashboard React. | E10: Opus/Sonnet | F10: =COUNTA(P5_Gold_API_UI!$A$2:$A$200) -> 8 | G10: =COUNTIF(P5_Gold_API_UI!$L$2:$L$200,"Non fait") -> 8 | H10: =COUNTIF(P5_Gold_API_UI!$L$2:$L$200,"En cours") -> 0 | I10: =COUNTIF(P5_Gold_API_UI!$L$2:$L$200,"À valider") -> 0 | J10: =COUNTIF(P5_Gold_API_UI!$L$2:$L$200,"Validé") -> 0 | K10: =IF(F10=0,0,J10/F10) -> 0 | L10: Non | M10: API + dashboard démontrables
A11: P6 | B11: P6_Observabilite_Optim | C11: Observabilité, remédiation & auto-optimisation | D11: Audit, alerting, auto-rejeu, optimisation par usage, sécurité, benchmarks. | E11: Opus/Sonnet | F11: =COUNTA(P6_Observabilite_Optim!$A$2:$A$200) -> 9 | G11: =COUNTIF(P6_Observabilite_Optim!$L$2:$L$200,"Non fait") -> 9 | H11: =COUNTIF(P6_Observabilite_Optim!$L$2:$L$200,"En cours") -> 0 | I11: =COUNTIF(P6_Observabilite_Optim!$L$2:$L$200,"À valider") -> 0 | J11: =COUNTIF(P6_Observabilite_Optim!$L$2:$L$200,"Validé") -> 0 | K11: =IF(F11=0,0,J11/F11) -> 0 | L11: Non | M11: Plateforme self-healing mesurée
A12: P7 | B12: P7_Portfolio_CV | C12: Portfolio, démo & candidature | D12: README, doc, démo reproductible, vidéo, étude de cas BA/BIA, CV, release v1.0. | E12: Haiku/Sonnet/Opus | F12: =COUNTA(P7_Portfolio_CV!$A$2:$A$200) -> 8 | G12: =COUNTIF(P7_Portfolio_CV!$L$2:$L$200,"Non fait") -> 8 | H12: =COUNTIF(P7_Portfolio_CV!$L$2:$L$200,"En cours") -> 0 | I12: =COUNTIF(P7_Portfolio_CV!$L$2:$L$200,"À valider") -> 0 | J12: =COUNTIF(P7_Portfolio_CV!$L$2:$L$200,"Validé") -> 0 | K12: =IF(F12=0,0,J12/F12) -> 0 | L12: Non | M12: Dossier de candidature complet
C13: TOTAL | F13: =SUM(F5:F12) -> 64 | G13: =SUM(G5:G12) -> 64 | H13: =SUM(H5:H12) -> 0 | I13: =SUM(I5:I12) -> 0 | J13: =SUM(J5:J12) -> 0 | K13: =IF(F13=0,0,J13/F13) -> 0
A15: Ordre d'exécution (séquentiel — une phase à la fois, validée avant de lancer la suivante)
A16: Ordre | B16: ID | C16: Phase | D16: Tâche | E16: Dépendances | F16: Modèle | G16: Statut
A17: =P0_Fondations!B2 -> 1 | B17: =P0_Fondations!A2 -> P0-01 | C17: P0 | D17: =P0_Fondations!C2 -> Structure du repo & outillage Python | E17: =P0_Fondations!I2 -> — | F17: =P0_Fondations!H2 -> Haiku | G17: =P0_Fondations!L2 -> Non fait
A18: =P0_Fondations!B3 -> 2 | B18: =P0_Fondations!A3 -> P0-02 | C18: P0 | D18: =P0_Fondations!C3 -> Docker Compose local (MinIO, Postgres) | E18: =P0_Fondations!I3 -> P0-01 | F18: =P0_Fondations!H3 -> Sonnet | G18: =P0_Fondations!L3 -> Non fait
A19: =P0_Fondations!B4 -> 3 | B19: =P0_Fondations!A4 -> P0-03 | C19: P0 | D19: =P0_Fondations!C4 -> Configuration & gestion des secrets | E19: =P0_Fondations!I4 -> P0-01 | F19: =P0_Fondations!H4 -> Sonnet | G19: =P0_Fondations!L4 -> Non fait
A20: =P0_Fondations!B5 -> 4 | B20: =P0_Fondations!A5 -> P0-04 | C20: P0 | D20: =P0_Fondations!C5 -> Logging structuré & modèle d'erreurs commun | E20: =P0_Fondations!I5 -> P0-01 | F20: =P0_Fondations!H5 -> Sonnet | G20: =P0_Fondations!L5 -> Non fait
A21: =P0_Fondations!B6 -> 5 | B21: =P0_Fondations!A6 -> P0-05 | C21: P0 | D21: =P0_Fondations!C6 -> CI GitHub Actions | E21: =P0_Fondations!I6 -> P0-01 | F21: =P0_Fondations!H6 -> Sonnet | G21: =P0_Fondations!L6 -> Non fait
A22: =P0_Fondations!B7 -> 6 | B22: =P0_Fondations!A7 -> P0-06 | C22: P0 | D22: =P0_Fondations!C7 -> Installer graphify et cartographier le repo | E22: =P0_Fondations!I7 -> P0-01 | F22: =P0_Fondations!H7 -> Haiku | G22: =P0_Fondations!L7 -> Non fait
A23: =P0_Fondations!B8 -> 7 | B23: =P0_Fondations!A8 -> P0-07 | C23: P0 | D23: =P0_Fondations!C8 -> ADR d'architecture fondatrices | E23: =P0_Fondations!I8 -> P0-02 | F23: =P0_Fondations!H8 -> Opus | G23: =P0_Fondations!L8 -> Non fait
A24: =P1_Ingestion_Bronze!B2 -> 8 | B24: =P1_Ingestion_Bronze!A2 -> P1-01 | C24: P1 | D24: =P1_Ingestion_Bronze!C2 -> Contrat de source & registry de sources | E24: =P1_Ingestion_Bronze!I2 -> P0-04 | F24: =P1_Ingestion_Bronze!H2 -> Sonnet | G24: =P1_Ingestion_Bronze!L2 -> Non fait
A25: =P1_Ingestion_Bronze!B3 -> 9 | B25: =P1_Ingestion_Bronze!A3 -> P1-02 | C25: P1 | D25: =P1_Ingestion_Bronze!C3 -> Connecteur fichiers (CSV/Excel/JSON) | E25: =P1_Ingestion_Bronze!I3 -> P1-01 | F25: =P1_Ingestion_Bronze!H3 -> Sonnet | G25: =P1_Ingestion_Bronze!L3 -> Non fait
A26: =P1_Ingestion_Bronze!B4 -> 10 | B26: =P1_Ingestion_Bronze!A4 -> P1-03 | C26: P1 | D26: =P1_Ingestion_Bronze!C4 -> Connecteur REST API | E26: =P1_Ingestion_Bronze!I4 -> P1-01 | F26: =P1_Ingestion_Bronze!H4 -> Sonnet | G26: =P1_Ingestion_Bronze!L4 -> Non fait
A27: =P1_Ingestion_Bronze!B5 -> 11 | B27: =P1_Ingestion_Bronze!A5 -> P1-04 | C27: P1 | D27: =P1_Ingestion_Bronze!C5 -> Connecteur base de données (incrémental) | E27: =P1_Ingestion_Bronze!I5 -> P1-01 | F27: =P1_Ingestion_Bronze!H5 -> Sonnet | G27: =P1_Ingestion_Bronze!L5 -> Non fait
A28: =P1_Ingestion_Bronze!B6 -> 12 | B28: =P1_Ingestion_Bronze!A6 -> P1-05 | C28: P1 | D28: =P1_Ingestion_Bronze!C6 -> Écriture Bronze immuable | E28: =P1_Ingestion_Bronze!I6 -> P1-02, P0-02 | F28: =P1_Ingestion_Bronze!H6 -> Sonnet | G28: =P1_Ingestion_Bronze!L6 -> Non fait
A29: =P1_Ingestion_Bronze!B7 -> 13 | B29: =P1_Ingestion_Bronze!A7 -> P1-06 | C29: P1 | D29: =P1_Ingestion_Bronze!C7 -> Gestion des erreurs d'ingestion & dead-letter | E29: =P1_Ingestion_Bronze!I7 -> P1-05 | F29: =P1_Ingestion_Bronze!H7 -> Sonnet | G29: =P1_Ingestion_Bronze!L7 -> Non fait
A30: =P1_Ingestion_Bronze!B8 -> 14 | B30: =P1_Ingestion_Bronze!A8 -> P1-07 | C30: P1 | D30: =P1_Ingestion_Bronze!C8 -> Simulateur de dérive de schéma | E30: =P1_Ingestion_Bronze!I8 -> P1-02 | F30: =P1_Ingestion_Bronze!H8 -> Sonnet | G30: =P1_Ingestion_Bronze!L8 -> Non fait
A31: =P1_Ingestion_Bronze!B9 -> 15 | B31: =P1_Ingestion_Bronze!A9 -> P1-08 | C31: P1 | D31: =P1_Ingestion_Bronze!C9 -> Archivage & cycle de vie Bronze | E31: =P1_Ingestion_Bronze!I9 -> P1-05 | F31: =P1_Ingestion_Bronze!H9 -> Sonnet | G31: =P1_Ingestion_Bronze!L9 -> Non fait
A32: =P1_Ingestion_Bronze!B10 -> 16 | B32: =P1_Ingestion_Bronze!A10 -> P1-09 | C32: P1 | D32: =P1_Ingestion_Bronze!C10 -> Assets & sensors Dagster d'ingestion | E32: =P1_Ingestion_Bronze!I10 -> P1-05, P1-06 | F32: =P1_Ingestion_Bronze!H10 -> Sonnet | G32: =P1_Ingestion_Bronze!L10 -> Non fait
A33: =P2_Schema_Evolution!B2 -> 17 | B33: =P2_Schema_Evolution!A2 -> P2-01 | C33: P2 | D33: =P2_Schema_Evolution!C2 -> Profilage & empreinte de schéma | E33: =P2_Schema_Evolution!I2 -> P1-05 | F33: =P2_Schema_Evolution!H2 -> Sonnet | G33: =P2_Schema_Evolution!L2 -> Non fait
A34: =P2_Schema_Evolution!B3 -> 18 | B34: =P2_Schema_Evolution!A3 -> P2-02 | C34: P2 | D34: =P2_Schema_Evolution!C3 -> Schema registry versionné | E34: =P2_Schema_Evolution!I3 -> P2-01, P0-02 | F34: =P2_Schema_Evolution!H3 -> Opus | G34: =P2_Schema_Evolution!L3 -> Non fait
A35: =P2_Schema_Evolution!B4 -> 19 | B35: =P2_Schema_Evolution!A4 -> P2-03 | C35: P2 | D35: =P2_Schema_Evolution!C4 -> Moteur de diff de schémas | E35: =P2_Schema_Evolution!I4 -> P2-02, P1-07 | F35: =P2_Schema_Evolution!H4 -> Opus | G35: =P2_Schema_Evolution!L4 -> Non fait
A36: =P2_Schema_Evolution!B5 -> 20 | B36: =P2_Schema_Evolution!A5 -> P2-04 | C36: P2 | D36: =P2_Schema_Evolution!C5 -> Classification d'impact & politique d'évolution | E36: =P2_Schema_Evolution!I5 -> P2-03 | F36: =P2_Schema_Evolution!H5 -> Opus | G36: =P2_Schema_Evolution!L5 -> Non fait
A37: =P2_Schema_Evolution!B6 -> 21 | B37: =P2_Schema_Evolution!A6 -> P2-05 | C37: P2 | D37: =P2_Schema_Evolution!C6 -> Rapport d'évolution & événements | E37: =P2_Schema_Evolution!I6 -> P2-04 | F37: =P2_Schema_Evolution!H6 -> Haiku | G37: =P2_Schema_Evolution!L6 -> Non fait
A38: =P2_Schema_Evolution!B7 -> 22 | B38: =P2_Schema_Evolution!A7 -> P2-06 | C38: P2 | D38: =P2_Schema_Evolution!C7 -> Intégration à l'ingestion (détection automatique) | E38: =P2_Schema_Evolution!I7 -> P2-04, P1-09 | F38: =P2_Schema_Evolution!H7 -> Sonnet | G38: =P2_Schema_Evolution!L7 -> Non fait
A39: =P2_Schema_Evolution!B8 -> 23 | B39: =P2_Schema_Evolution!A8 -> P2-07 | C39: P2 | D39: =P2_Schema_Evolution!C8 -> Tests de propriétés du diff | E39: =P2_Schema_Evolution!I8 -> P2-03 | F39: =P2_Schema_Evolution!H8 -> Sonnet | G39: =P2_Schema_Evolution!L8 -> Non fait
A40: =P3_Mapping_Silver!B2 -> 24 | B40: =P3_Mapping_Silver!A2 -> P3-01 | C40: P3 | D40: =P3_Mapping_Silver!C2 -> Modèle canonique & dictionnaire sémantique | E40: =P3_Mapping_Silver!I2 -> P2-01 | F40: =P3_Mapping_Silver!H2 -> Sonnet | G40: =P3_Mapping_Silver!L2 -> Non fait
A41: =P3_Mapping_Silver!B3 -> 25 | B41: =P3_Mapping_Silver!A3 -> P3-02 | C41: P3 | D41: =P3_Mapping_Silver!C3 -> Mapping par règles & fuzzy | E41: =P3_Mapping_Silver!I3 -> P3-01 | F41: =P3_Mapping_Silver!H3 -> Sonnet | G41: =P3_Mapping_Silver!L3 -> Non fait
A42: =P3_Mapping_Silver!B4 -> 26 | B42: =P3_Mapping_Silver!A4 -> P3-03 | C42: P3 | D42: =P3_Mapping_Silver!C4 -> Mapping assisté par LLM + RAG | E42: =P3_Mapping_Silver!I4 -> P3-02 | F42: =P3_Mapping_Silver!H4 -> Opus | G42: =P3_Mapping_Silver!L4 -> Non fait
...

Sheet P0_Fondations
A1: ID | B1: Ordre | C1: Tâche | D1: Objectif | E1: Code à produire | F1: Explication & compétence CV | G1: Test de validation | H1: Modèle | I1: Dépendances | J1: Hypothèse | K1: Skills / plugins | L1: Statut | M1: Preuve / notes Claude
A2: P0-01 | B2: 1 | C2: Structure du repo & outillage Python | D2: Créer l'ossature du projet (src layout), gestion des dépendances et qualité de code. | E2: pyproject.toml (uv, ruff, mypy, pytest, openpyxl, duckdb, pydantic), src/adp/__init__.py, tests/test_smoke.py, Makefile (install, lint, test, demo), .pre-commit-config.yaml. | F2: Un repo reproductible en une commande est le premier signal de professionnalisme. Compétence : packaging Python moderne, tooling qualité. | G2: `uv sync && make lint && make test` → ruff sans erreur, 1 test smoke vert. | H2: Haiku | I2: — | J2: H-06 | K2: ponytail | L2: Non fait
A3: P0-02 | B3: 2 | C3: Docker Compose local (MinIO, Postgres) | D3: Environnement local reproductible : stockage objet S3 et base de métadonnées. | E3: docker-compose.yml (minio, postgres, minio-init créant les buckets bronze/silver/gold), scripts/healthcheck.py, .env.example. | F3: Simule un data lake S3 localement sans coût cloud. Compétence : conteneurisation, infra as code. | G3: `docker compose up -d && python scripts/healthcheck.py` → 3 buckets présents et Postgres répond (exit 0). | H3: Sonnet | I3: P0-01 | J3: H-04 | K3: ponytail | L3: Non fait
A4: P0-03 | B4: 3 | C4: Configuration & gestion des secrets | D4: Centraliser la config typée et garantir qu'aucun secret n'est commité. | E4: src/adp/config.py (pydantic-settings), .env.example complet, tests/test_config.py, hook pre-commit de détection de secrets. | F4: Séparation config/code (12-factor) et hygiène sécurité. Compétence : sécurité applicative, DevSecOps. | G4: `pytest tests/test_config.py` vert ; ajouter une fausse clé AKIA… dans un fichier → le pre-commit refuse le commit. | H4: Sonnet | I4: P0-01 | J4: — | K4: ponytail | L4: Non fait
A5: P0-04 | B5: 4 | C5: Logging structuré & modèle d'erreurs commun | D5: Logs JSON corrélés par run_id et hiérarchie d'exceptions du domaine. | E5: src/adp/logging.py (structlog), src/adp/errors.py (AdpError, SchemaError, QualityError, IngestionError), tests/test_logging.py. | F5: Base de l'observabilité (P6) : tout événement est traçable. Compétence : observabilité, design d'erreurs. | G5: `pytest tests/test_logging.py` → chaque ligne de log est du JSON valide contenant run_id, level, event. | H5: Sonnet | I5: P0-01 | J5: — | K5: ponytail | L5: Non fait
A6: P0-05 | B6: 5 | C6: CI GitHub Actions | D6: Pipeline CI : lint, typage, tests, sur chaque push/PR. | E6: .github/workflows/ci.yml (matrix Python 3.12, cache uv), badge dans README. | F6: Démontre l'intégration continue. Compétence : CI/CD. | G6: Push d'une branche → workflow vert dans l'onglet Actions ; casser volontairement un test → workflow rouge. | H6: Sonnet | I6: P0-01 | J6: — | K6: ponytail | L6: Non fait
A7: P0-06 | B7: 6 | C7: Installer graphify et cartographier le repo | D7: Générer le graphe de connaissance du projet pour réduire les tokens de contexte. | E7: scripts/setup_tools.sh (pip install graphifyy && graphify install), graphify-out/ (GRAPH_REPORT.md, graph.json), règle dans CLAUDE.md pour lire GRAPH_REPORT.md avant d'explorer. | F7: Graphe de code interrogeable = navigation rapide et moins coûteuse. Compétence : outillage agentique, knowledge graph. | G7: `graphify .` produit GRAPH_REPORT.md non vide ; `git status` montre graph.json ignoré ou commité selon la décision H-07. | H7: Haiku | I7: P0-01 | J7: H-07 | K7: graphify | L7: Non fait
A8: P0-07 | B8: 7 | C8: ADR d'architecture fondatrices | D8: Documenter les décisions structurantes : médaillon, stockage, metadata store, orchestrateur, politique LLM. | E8: docs/adr/0001-medallion.md … 0006-llm-policy.md (contexte/décision/conséquences), docs/architecture.md avec diagramme Mermaid. | F8: Les ADR montrent le raisonnement d'un architecte, pas seulement du code. Compétence : architecture de données. | G8: `pytest tests/test_docs.py` : chaque ADR contient les 3 sections ; le diagramme Mermaid est rendu sur GitHub. | H8: Opus | I8: P0-02 | J8: H-03, H-04 | K8: ponytail, graphify | L8: Non fait

Sheet P1_Ingestion_Bronze
A1: ID | B1: Ordre | C1: Tâche | D1: Objectif | E1: Code à produire | F1: Explication & compétence CV | G1: Test de validation | H1: Modèle | I1: Dépendances | J1: Hypothèse | K1: Skills / plugins | L1: Statut | M1: Preuve / notes Claude
A2: P1-01 | B2: 8 | C2: Contrat de source & registry de sources | D2: Décrire chaque source de façon déclarative. | E2: src/adp/sources/spec.py (SourceSpec pydantic : type, uri, auth ref, format, fréquence, clé), config/sources/*.yaml, loader + validation. | F2: Le contrat de source rend l'ajout d'une source déclaratif. Compétence : data contracts. | G2: `pytest tests/sources/test_spec.py` : un YAML valide charge, un YAML invalide lève SourceSpecError avec message clair. | H2: Sonnet | I2: P0-04 | J2: H-01 | K2: ponytail | L2: Non fait
A3: P1-02 | B3: 9 | C3: Connecteur fichiers (CSV/Excel/JSON) | D3: Lire des fichiers hétérogènes avec détection auto d'encodage, délimiteur et feuille. | E3: src/adp/connectors/files.py (charset-normalizer, csv.Sniffer, openpyxl), fixtures dans tests/data/. | F3: Les fichiers sales sont la réalité du terrain. Compétence : ingestion robuste. | G3: `pytest tests/connectors/test_files.py` : CSV latin-1 `;`, CSV utf-8 `,`, XLSX multi-feuilles, JSON lines → DataFrame correct. | H3: Sonnet | I3: P1-01 | J3: — | K3: ponytail | L3: Non fait
A4: P1-03 | B4: 10 | C4: Connecteur REST API | D4: Ingestion d'API paginées avec retry, backoff et limite de débit. | E4: src/adp/connectors/rest.py (httpx, tenacity), pagination page/offset/cursor, tests avec respx. | F4: Résilience réseau et pagination. Compétence : API ingestion. | G4: `pytest tests/connectors/test_rest.py` : 3 pages agrégées, 2 erreurs 503 puis succès (retry), 429 respecte Retry-After. | H4: Sonnet | I4: P1-01 | J4: H-01 | K4: ponytail | L4: Non fait
A5: P1-04 | B5: 11 | C5: Connecteur base de données (incrémental) | D5: Extraction SQL avec watermark pour ne lire que le nouveau. | E5: src/adp/connectors/sql.py (SQLAlchemy), table de watermarks, tests sur SQLite et Postgres de test. | F5: Chargement incrémental = coût et fraîcheur maîtrisés. Compétence : CDC léger. | G5: `pytest tests/connectors/test_sql.py` : 2e exécution sans nouvelle ligne → 0 ligne lue ; après insert de 5 lignes → 5 lues. | H5: Sonnet | I5: P1-01 | J5: — | K5: ponytail | L5: Non fait
A6: P1-05 | B6: 12 | C6: Écriture Bronze immuable | D6: Persister le brut en Parquet sur MinIO avec métadonnées et idempotence. | E6: src/adp/bronze/writer.py : partition source/ingestion_date, colonnes techniques (_run_id, _ingested_at, _source, _row_hash), manifeste JSON, écriture atomique. | F6: Immuabilité + traçabilité = auditabilité. Compétence : lakehouse, idempotence. | G6: `pytest tests/bronze/test_writer.py` : rejouer le même lot ne crée pas de doublon ; le manifeste contient hash et nb lignes ; fichier jamais modifié après écriture. | H6: Sonnet | I6: P1-02, P0-02 | J6: — | K6: ponytail | L6: Non fait
A7: P1-06 | B7: 13 | C7: Gestion des erreurs d'ingestion & dead-letter | D7: Ne jamais perdre une ligne : les rejets sont stockés avec leur raison. | E7: src/adp/bronze/deadletter.py, schéma de rejet (raison, ligne brute, source, run_id), politique de retry. | F7: Pas de perte silencieuse de données. Compétence : fiabilité des pipelines. | G7: `pytest tests/bronze/test_deadletter.py` : fichier avec 3 lignes corrompues sur 100 → 97 en Bronze, 3 en dead-letter avec motif. | H7: Sonnet | I7: P1-05 | J7: — | K7: ponytail | L7: Non fait
A8: P1-07 | B8: 14 | C8: Simulateur de dérive de schéma | D8: Générer des jeux v1→v2→v3 reproductibles (colonne ajoutée, renommée, type changé). | E8: scripts/drift_simulator.py (seed fixe), tests/data/drift/{v1,v2,v3}/, README du scénario de démo. | F8: Donne un banc d'essai déterministe pour P2/P3 et la démo. Compétence : data engineering de test. | G8: `python scripts/drift_simulator.py --seed 42` deux fois → fichiers identiques (hash égal) ; diff v1/v2 documenté. | H8: Sonnet | I8: P1-02 | J8: H-01 | K8: ponytail | L8: Non fait
A9: P1-08 | B9: 15 | C9: Archivage & cycle de vie Bronze | D9: Règles de rétention et d'archivage configurables. | E9: src/adp/bronze/lifecycle.py, config/retention.yaml, commande CLI `adp bronze archive --dry-run`. | F9: Gouvernance et coûts de stockage. Compétence : data lifecycle. | G9: `pytest tests/bronze/test_lifecycle.py` : lots > rétention archivés, récents intacts ; --dry-run ne modifie rien. | H9: Sonnet | I9: P1-05 | J9: — | K9: ponytail | L9: Non fait
A10: P1-09 | B10: 16 | C10: Assets & sensors Dagster d'ingestion | D10: Orchestrer l'ingestion avec Dagster (assets, partitions, sensors). | E10: src/adp/orchestration/ingestion.py, definitions.py, dagster.yaml, test de matérialisation. | F10: Orchestration déclarative avec lignage natif. Compétence : Dagster. | G10: `dagster asset materialize -m adp.orchestration` → asset Bronze matérialisé ; `pytest tests/orchestration` vert. | H10: Sonnet | I10: P1-05, P1-06 | J10: H-08 | K10: ponytail | L10: Non fait

Sheet P2_Schema_Evolution
A1: ID | B1: Ordre | C1: Tâche | D1: Objectif | E1: Code à produire | F1: Explication & compétence CV | G1: Test de validation | H1: Modèle | I1: Dépendances | J1: Hypothèse | K1: Skills / plugins | L1: Statut | M1: Preuve / notes Claude
A2: P2-01 | B2: 17 | C2: Profilage & empreinte de schéma | D2: Extraire pour chaque colonne : type inféré, nullabilité, cardinalité, stats, exemples. | E2: src/adp/schema/profile.py (ColumnProfile, SchemaFingerprint), inférence de type robuste (dates, nombres FR/EN). | F2: Le profil est l'entrée de la détection et du mapping. Compétence : data profiling. | G2: `pytest tests/schema/test_profile.py` : '12,5' et '12.5' → float ; '2024-01-31' et '31/01/2024' → date ; empreinte stable pour mêmes données. | H2: Sonnet | I2: P1-05 | J2: — | K2: ponytail | L2: Non fait
A3: P2-02 | B3: 18 | C3: Schema registry versionné | D3: Stocker chaque version de schéma par source avec hash et versioning sémantique. | E3: src/adp/schema/registry.py (SQLAlchemy, tables schema_version, schema_change), migrations Alembic, API register/get/latest/history. | F3: Mémoire des schémas = base de toute évolution gouvernée. Compétence : metadata management. | G3: `pytest tests/schema/test_registry.py` : même schéma → même version (idempotent) ; changement → version+1 ; historique ordonné. | H3: Opus | I3: P2-01, P0-02 | J3: H-04 | K3: ponytail, graphify | L3: Non fait
A4: P2-03 | B4: 19 | C4: Moteur de diff de schémas | D4: Détecter ajout, suppression, changement de type et renommage probable (score de similarité). | E4: src/adp/schema/diff.py (SchemaDiff, ChangeKind), heuristique de renommage (nom + type + distribution), seuils configurables. | F4: Cœur différenciant : distinguer renommage vs suppression+ajout. Compétence : algorithmique de similarité. | G4: `pytest tests/schema/test_diff.py` sur v1→v2→v3 du simulateur : renommage détecté avec score ≥ seuil, 0 faux positif sur 20 cas témoins. | H4: Opus | I4: P2-02, P1-07 | J4: H-03 | K4: ponytail, graphify | L4: Non fait
A5: P2-04 | B5: 20 | C5: Classification d'impact & politique d'évolution | D5: Classer chaque changement : compatible / à revoir / bloquant, et définir l'action automatique. | E5: src/adp/schema/policy.py, config/evolution_policy.yaml (règles par ChangeKind), ChangeImpact enum. | F5: Traduit la technique en risque métier (lien BIA). Compétence : gouvernance, analyse d'impact. | G5: `pytest tests/schema/test_policy.py` : suppression de clé → BLOQUANT ; ajout de colonne nullable → COMPATIBLE ; widening int→float → COMPATIBLE. | H5: Opus | I5: P2-03 | J5: H-02 | K5: ponytail | L5: Non fait
A6: P2-05 | B6: 21 | C6: Rapport d'évolution & événements | D6: Produire un rapport lisible et émettre un événement à chaque changement. | E6: src/adp/schema/report.py (Markdown + JSON), bus d'événements interne (SchemaChanged). | F6: Rendre le changement visible aux humains et aux systèmes. Compétence : communication data. | G6: `pytest tests/schema/test_report.py` : rapport contient version avant/après, liste des changements, impact ; événement émis une seule fois. | H6: Haiku | I6: P2-04 | J6: — | K6: ponytail | L6: Non fait
A7: P2-06 | B7: 22 | C7: Intégration à l'ingestion (détection automatique) | D7: À chaque lot : profil → diff → politique ; bloquer ou continuer. | E7: src/adp/orchestration/schema_gate.py, asset Dagster schema_check entre Bronze et Silver. | F7: Automatisation bout en bout de la détection. Compétence : intégration de pipeline. | G7: Run Dagster sur v1 puis v2 → v2 passe avec rapport ; v3 (breaking) → arrêt propre avec statut 'blocked' et motif. | H7: Sonnet | I7: P2-04, P1-09 | J7: — | K7: ponytail | L7: Non fait
A8: P2-07 | B8: 23 | C8: Tests de propriétés du diff | D8: Renforcer la fiabilité du diff avec du property-based testing. | E8: tests/schema/test_diff_properties.py (hypothesis) : diff(a,a)=∅, symétrie des ajouts/suppressions, stabilité à l'ordre des colonnes. | F8: Preuve de rigueur de test. Compétence : property-based testing. | G8: `pytest tests/schema/test_diff_properties.py` : 500 exemples générés, 0 contre-exemple. | H8: Sonnet | I8: P2-03 | J8: — | K8: ponytail | L8: Non fait

Sheet P3_Mapping_Silver
A1: ID | B1: Ordre | C1: Tâche | D1: Objectif | E1: Code à produire | F1: Explication & compétence CV | G1: Test de validation | H1: Modèle | I1: Dépendances | J1: Hypothèse | K1: Skills / plugins | L1: Statut | M1: Preuve / notes Claude
A2: P3-01 | B2: 24 | C2: Modèle canonique & dictionnaire sémantique | D2: Définir les champs cibles et leurs synonymes (FR/EN). | E2: config/semantic/canonical.yaml (champ, type, description, synonymes, unité), src/adp/mapping/dictionary.py. | F2: Le référentiel sémantique est ce qui rend le mapping intelligent. Compétence : modélisation sémantique, BA. | G2: `pytest tests/mapping/test_dictionary.py` : chargement valide, doublon de synonyme détecté, recherche insensible à la casse/accents. | H2: Sonnet | I2: P2-01 | J2: H-01 | K2: ponytail | L2: Non fait
A3: P3-02 | B3: 25 | C3: Mapping par règles & fuzzy | D3: Premier niveau déterministe : exact, normalisé, synonyme, fuzzy (rapidfuzz) avec score. | E3: src/adp/mapping/rules.py (MappingCandidate{source_col,target,score,method}), normalisation (accents, casse, séparateurs). | F3: Baseline explicable avant tout LLM. Compétence : NLP léger, baseline-first. | G3: `pytest tests/mapping/test_rules.py` : 'N° Client' → customer_id (méthode normalisé) ; 'cust_nm' → customer_name (fuzzy ≥ seuil). | H3: Sonnet | I3: P3-01 | J3: — | K3: ponytail | L3: Non fait
A4: P3-03 | B4: 26 | C4: Mapping assisté par LLM + RAG | D4: Proposer des mappings pour les colonnes non résolues via embeddings + LLM, sortie JSON validée. | E4: src/adp/mapping/llm.py (interface LLMProvider, Claude via SDK anthropic, fallback local), embeddings du glossaire, prompt structuré, validation pydantic, cache disque. | F4: Le LLM propose, ne décide pas. Compétence : LLM/RAG appliqué, prompt engineering, sorties structurées. | G4: `pytest tests/mapping/test_llm.py` avec provider simulé : JSON invalide rejeté, réponse hors glossaire rejetée, cache évite 2e appel ; test d'intégration marqué `slow` avec vraie clé. | H4: Opus | I4: P3-02 | J4: H-09 | K4: ponytail, graphify | L4: Non fait
A5: P3-04 | B5: 27 | C5: Politique de décision & revue humaine | D5: Auto-appliquer au-dessus d'un seuil, sinon file de revue (human-in-the-loop). | E5: src/adp/mapping/decision.py, table review_queue, CLI `adp review list/approve/reject`, journalisation de chaque décision. | F5: Contrôle du risque IA : traçabilité et réversibilité. Compétence : IA responsable, gouvernance. | G5: `pytest tests/mapping/test_decision.py` : score 0.95 → auto ; 0.7 → file ; décision approuvée enregistrée avec auteur et horodatage. | H5: Opus | I5: P3-02, P3-03 | J5: H-02 | K5: ponytail | L5: Non fait
A6: P3-05 | B6: 28 | C6: Transformations de types sûres | D6: Appliquer conversions et règles de transformation sans exécution de code arbitraire. | E6: src/adp/mapping/transform.py : DSL déclaratif (cast, parse_date, strip, map_values, unit_convert), évaluateur whitelisté, erreurs par ligne vers dead-letter. | F6: Évite l'injection via sortie LLM. Compétence : sécurité, conception de DSL. | G6: `pytest tests/mapping/test_transform.py` : transformation inconnue refusée ; tentative `__import__` dans une règle rejetée ; conversions correctes. | H6: Opus | I6: P3-04 | J6: — | K6: ponytail | L6: Non fait
A7: P3-06 | B7: 29 | C7: Nettoyage & normalisation | D7: Standardiser texte, dates, nombres, unités et valeurs manquantes. | E7: src/adp/silver/clean.py, règles par champ canonique, journal des corrections. | F7: Qualité à la source de Silver. Compétence : data cleansing. | G7: `pytest tests/silver/test_clean.py` : espaces/casse/accents normalisés, dates → ISO 8601, 'N/A','-','' → null. | H7: Sonnet | I7: P3-05 | J7: — | K7: ponytail | L7: Non fait
A8: P3-07 | B8: 30 | C8: Déduplication | D8: Dédoublonnage exact et approximatif (blocking + similarité). | E8: src/adp/silver/dedup.py (clés naturelles, blocking, rapidfuzz), règle de survivance, rapport de doublons. | F8: Entity resolution de base. Compétence : data science appliquée. | G8: `pytest tests/silver/test_dedup.py` : 10 doublons injectés sur 1000 lignes → 10 trouvés, 0 faux positif. | H8: Sonnet | I8: P3-06 | J8: — | K8: ponytail | L8: Non fait
A9: P3-08 | B9: 31 | C9: Écriture Silver & apprentissage du dictionnaire | D9: Écrire Silver et enrichir automatiquement les synonymes avec les mappings validés. | E9: src/adp/silver/writer.py (Parquet typé, versionné par schéma), src/adp/mapping/learn.py (ajout de synonymes validés, jamais non validés). | F9: Boucle d'amélioration continue. Compétence : MLOps léger, feedback loop. | G9: `pytest tests/silver/test_writer.py tests/mapping/test_learn.py` : mapping approuvé → synonyme ajouté ; au prochain run même colonne résolue par règle sans LLM. | H9: Sonnet | I9: P3-07 | J9: — | K9: ponytail | L9: Non fait
A10: P3-09 | B10: 32 | C10: Évaluation du mapping (jeu annoté) | D10: Mesurer précision/rappel des mappings règles vs règles+LLM. | E10: tests/data/gold_mappings.csv (≥100 colonnes annotées), src/adp/mapping/eval.py, rapport docs/eval/mapping.md avec matrice de confusion. | F10: Une métrique chiffrée vaut mille promesses — argument fort en entretien. Compétence : évaluation de modèles. | G10: `python -m adp.mapping.eval` → rapport généré ; précision règles+LLM ≥ précision règles seules (seuil à fixer, voir H-09). | H10: Sonnet | I10: P3-03, P3-08 | J10: H-09 | K10: ponytail | L10: Non fait

Sheet P4_Qualite_Quarantaine
A1: ID | B1: Ordre | C1: Tâche | D1: Objectif | E1: Code à produire | F1: Explication & compétence CV | G1: Test de validation | H1: Modèle | I1: Dépendances | J1: Hypothèse | K1: Skills / plugins | L1: Statut | M1: Preuve / notes Claude
A2: P4-01 | B2: 33 | C2: Moteur de règles qualité | D2: Règles déclaratives : not_null, unique, plage, regex, référentiel, fraîcheur. | E2: src/adp/quality/rules.py, config/quality/*.yaml, résultats par règle (passé/échoué/lignes). | F2: Qualité codée comme contrat. Compétence : data quality engineering. | G2: `pytest tests/quality/test_rules.py` : chaque type de règle testé passant et échouant, avec nombre de lignes en échec correct. | H2: Sonnet | I2: P3-08 | J2: — | K2: ponytail | L2: Non fait
A3: P4-02 | B3: 34 | C3: Anomalies & dérive de distribution | D3: Détecter valeurs aberrantes et dérive entre lots (z-score/IQR, PSI, KS). | E3: src/adp/quality/anomaly.py, src/adp/quality/drift.py, seuils configurables. | F3: Statistiques appliquées à la fiabilité. Compétence : data science, monitoring de dérive. | G3: `pytest tests/quality/test_anomaly.py` : outlier injecté détecté ; deux échantillons même loi → pas d'alerte ; décalage de moyenne → PSI > seuil. | H3: Sonnet | I3: P4-01 | J3: — | K3: ponytail | L3: Non fait
A4: P4-03 | B4: 35 | C4: Score de qualité | D4: Score par colonne et par lot (complétude, validité, unicité, fraîcheur). | E4: src/adp/quality/score.py, pondération configurable, persistance par run. | F4: Résumer la qualité en un indicateur actionnable (BIA). Compétence : KPI data. | G4: `pytest tests/quality/test_score.py` : jeu parfait = 100 ; 10 % de nulls sur colonne obligatoire → complétude 90 ; poids respectés. | H4: Sonnet | I4: P4-01 | J4: — | K4: ponytail | L4: Non fait
A5: P4-04 | B5: 36 | C5: Quarantaine dynamique | D5: Isoler lignes ou lots en échec qualité sans bloquer le reste, avec rejeu possible. | E5: src/adp/quality/quarantine.py (niveau ligne/lot, motifs, statut), commande `adp quarantine release/replay`. | F5: Isolation du risque et reprise contrôlée. Compétence : conception de pipelines résilients. | G5: `pytest tests/quality/test_quarantine.py` : 5 % de lignes invalides → mises en quarantaine, 95 % passent ; lot sous seuil critique → lot entier isolé ; replay après correction réussit. | H5: Opus | I5: P4-01, P4-03 | J5: H-02 | K5: ponytail, graphify | L5: Non fait
A6: P4-05 | B6: 37 | C6: Rapports de qualité | D6: Rapport HTML/JSON par run, lisible par un métier. | E6: src/adp/quality/report.py, templates Jinja2, export vers docs/samples/. | F6: Communication vers les parties prenantes. Compétence : data storytelling. | G6: `pytest tests/quality/test_report.py` : HTML valide contenant score, règles en échec, top anomalies. | H6: Haiku | I6: P4-03 | J6: — | K6: ponytail | L6: Non fait
A7: P4-06 | B7: 38 | C7: Contrôles métier & cohérence | D7: Règles inter-colonnes et inter-sources (ex. date_fin ≥ date_debut, totaux). | E7: config/quality/business_rules.yaml, extension du moteur pour expressions SQL DuckDB whitelistées. | F7: Capte la logique métier, pas seulement technique. Compétence : analyse métier (BA). | G7: `pytest tests/quality/test_business_rules.py` : violation détectée avec lignes identifiées ; expression non autorisée refusée. | H7: Sonnet | I7: P4-01 | J7: — | K7: ponytail | L7: Non fait
A8: P4-07 | B8: 39 | C8: Validation finale Silver → Gold | D8: Gate final : le lot n'est promu que si score et règles critiques passent. | E8: src/adp/orchestration/promotion_gate.py, asset Dagster promote_to_gold. | F8: Garantit que Gold = données de confiance. Compétence : data governance. | G8: Run Dagster : lot conforme → promu ; lot avec règle critique en échec → non promu, statut 'quarantined' et rapport disponible. | H8: Sonnet | I8: P4-04, P4-06 | J8: — | K8: ponytail | L8: Non fait

Sheet P5_Gold_API_UI
A1: ID | B1: Ordre | C1: Tâche | D1: Objectif | E1: Code à produire | F1: Explication & compétence CV | G1: Test de validation | H1: Modèle | I1: Dépendances | J1: Hypothèse | K1: Skills / plugins | L1: Statut | M1: Preuve / notes Claude
A2: P5-01 | B2: 40 | C2: Modèle Gold & contrats de data products | D2: Définir les data products avec owner, SLA, criticité et consommateurs (analyse d'impact BIA). | E2: config/products/*.yaml (nom, schéma, owner, SLA fraîcheur, criticité, consommateurs), src/adp/gold/contract.py, matrice d'impact docs/bia.md. | F2: Relie la technique aux enjeux métier : démontre BA + BIA. Compétence : data product thinking. | G2: `pytest tests/gold/test_contract.py` : contrat sans owner ou SLA refusé ; matrice d'impact générée liste produits critiques. | H2: Opus | I2: P4-07 | J2: H-01, H-05 | K2: ponytail | L2: Non fait
A3: P5-02 | B3: 41 | C3: Vues & indicateurs DuckDB | D3: Construire les vues métier et indicateurs, matérialisées au besoin. | E3: src/adp/gold/views.py, sql/gold/*.sql, builder idempotent, tests sur jeu réduit. | F3: DuckDB comme moteur analytique embarqué. Compétence : SQL analytique. | G3: `pytest tests/gold/test_views.py` : indicateurs recalculés = valeurs attendues du jeu témoin ; rebuild idempotent. | H3: Sonnet | I3: P5-01 | J3: — | K3: ponytail | L3: Non fait
A4: P5-03 | B4: 42 | C4: API FastAPI | D4: Exposer data products, schémas, qualité et runs. | E4: src/adp/api/main.py, routers (products, schemas, quality, runs, health), auth par clé API, pagination, OpenAPI. | F4: Mise à disposition contrôlée de la donnée. Compétence : API design. | G4: `pytest tests/api` (TestClient) : 401 sans clé, 200 avec ; pagination correcte ; `/openapi.json` valide. | H4: Sonnet | I4: P5-02 | J4: — | K4: ponytail | L4: Non fait
A5: P5-04 | B5: 43 | C5: Catalogue de données & lignage | D5: Métadonnées actives : produits, colonnes, lignage source→Gold. | E5: src/adp/catalog/ (modèle, extraction du lignage depuis les runs, export OpenLineage-lite JSON), endpoint /catalog. | F5: Découvrabilité et confiance. Compétence : metadata management, lignage. | G5: `pytest tests/catalog` : lignage d'une colonne Gold remonte jusqu'à la source Bronze ; endpoint renvoie produits et owners. | H5: Sonnet | I5: P5-03 | J5: — | K5: ponytail | L5: Non fait
A6: P5-05 | B6: 44 | C6: Design system & maquettes de l'UI | D6: Définir style, palette, typographie et composants avant de coder. | E6: frontend/DESIGN.md (tokens, composants, écrans), maquettes statiques HTML dans frontend/mockups/. | F6: Cohérence visuelle = portfolio crédible. Compétence : UI/UX appliqué à la donnée. | G6: Revue : 4 écrans maquettés (pipeline, qualité, schémas, revue mapping) ; contraste AA vérifié ; validation par l'utilisateur à la gate. | H6: Sonnet | I6: P5-03 | J6: H-10 | K6: ui-ux-pro-max | L6: Non fait
A7: P5-06 | B7: 45 | C7: Dashboard React | D7: Interface de supervision : pipeline, qualité, évolutions de schéma, file de revue. | E7: frontend/ (Vite, React, TS, Tailwind, TanStack Query), pages et composants, client API typé. | F7: Rend la plateforme démontrable en 2 minutes. Compétence : front-end data apps. | G7: `cd frontend && npm run build && npm test` verts ; dashboard affiche les données de l'API de démo. | H7: Sonnet | I7: P5-05 | J7: H-10 | K7: ui-ux-pro-max | L7: Non fait
A8: P5-07 | B8: 46 | C8: Animations & micro-interactions | D8: Transitions sobres et fonctionnelles, respect de prefers-reduced-motion. | E8: Framer Motion (ou équivalent), transitions de pages, états de chargement/vides, hook useReducedMotion. | F8: Finition perçue sans nuire à l'accessibilité. Compétence : motion design UI. | G8: Test Vitest : animations désactivées si reduced-motion ; revue visuelle (captures) ; Lighthouse perf ≥ 85. | H8: Sonnet | I8: P5-06 | J8: H-10 | K8: ui-ux-pro-max, motion | L8: Non fait
A9: P5-08 | B9: 47 | C9: Tests E2E & accessibilité | D9: Parcours critiques automatisés et audit a11y. | E9: frontend/e2e/ (Playwright), axe-core dans les tests, job CI dédié. | F9: Qualité front mesurable. Compétence : test E2E, accessibilité. | G9: `npx playwright test` vert ; 0 violation axe 'serious/critical'. | H9: Sonnet | I9: P5-07 | J9: — | K9: ponytail | L9: Non fait

Sheet P6_Observabilite_Optim
A1: ID | B1: Ordre | C1: Tâche | D1: Objectif | E1: Code à produire | F1: Explication & compétence CV | G1: Test de validation | H1: Modèle | I1: Dépendances | J1: Hypothèse | K1: Skills / plugins | L1: Statut | M1: Preuve / notes Claude
A2: P6-01 | B2: 48 | C2: Audit & métriques | D2: Tables d'audit et métriques Prometheus pour chaque run. | E2: src/adp/observability/audit.py, metrics.py (prometheus-client), endpoint /metrics, tables run_audit, step_audit. | F2: Base de la fiabilité mesurée. Compétence : observabilité. | G2: `pytest tests/observability` ; `curl :8000/metrics` expose adp_runs_total, adp_quality_score, adp_schema_changes_total. | H2: Sonnet | I2: P5-03 | J2: — | K2: ponytail | L2: Non fait
A3: P6-02 | B3: 49 | C3: Alerting & analyse de cause racine | D3: Alertes webhook et explication LLM de la cause probable d'un échec. | E3: src/adp/observability/alerts.py (webhook Slack/Discord), rca.py (contexte logs+diff → hypothèses classées), anti-bruit (dédup, seuils). | F3: Réduit le MTTR. Compétence : AIOps, prompt engineering. | G3: `pytest tests/observability/test_alerts.py` : même alerte non répétée dans la fenêtre ; RCA sur échec simulé cite le changement de schéma réel. | H3: Opus | I3: P6-01, P3-03 | J3: H-09 | K3: ponytail | L3: Non fait
A4: P6-03 | B4: 50 | C4: Auto-rejeu intelligent | D4: Relancer automatiquement après correctif, de façon idempotente et bornée. | E4: src/adp/orchestration/replay.py : détection de correctif (mapping approuvé, règle modifiée), budget de retries, backoff, kill switch (config). | F4: Self-healing sans emballement. Compétence : conception de systèmes fiables. | G4: `pytest tests/orchestration/test_replay.py` : après approbation d'un mapping le lot bloqué est rejoué une fois ; budget épuisé → stop et alerte ; kill switch respecté ; rejeu sans doublons. | H4: Opus | I4: P6-02, P4-04 | J4: H-02 | K4: ponytail, graphify | L4: Non fait
A5: P6-04 | B5: 51 | C5: Dashboards Grafana as code | D5: Dashboards versionnés provisionnés automatiquement. | E5: infra/grafana/provisioning/ (datasources, dashboards JSON), ajout de Prometheus/Grafana au compose. | F5: Observabilité reproductible. Compétence : IaC monitoring. | G5: `docker compose up -d` → Grafana expose le dashboard 'ADP Overview' avec données. | H5: Haiku | I5: P6-01 | J5: — | K5: ponytail | L5: Non fait
A6: P6-05 | B6: 52 | C6: Auto-optimisation guidée par l'usage | D6: Analyser les requêtes API et proposer index / vues matérialisées. | E6: src/adp/optimizer/usage.py (journal de requêtes), advisor.py (règles de recommandation), application sous validation, rapport avant/après. | F6: Plateforme qui s'améliore seule, avec mesure. Compétence : performance data, optimisation. | G6: `pytest tests/optimizer` ; benchmark `make bench-optim` : latence p95 de la requête fréquente réduite d'au moins la cible fixée (H-11). | H6: Opus | I6: P6-01, P5-02 | J6: H-11 | K6: ponytail, graphify | L6: Non fait
A7: P6-06 | B7: 53 | C7: Compaction & rétention automatisées | D7: Compacter les petits fichiers et appliquer la rétention. | E7: src/adp/optimizer/compaction.py, jobs Dagster planifiés, métriques avant/après. | F7: Résout le small-files problem. Compétence : lakehouse ops. | G7: `pytest tests/optimizer/test_compaction.py` : 200 petits Parquet → N fichiers cibles, lignes identiques (hash) ; rétention appliquée. | H7: Sonnet | I7: P6-05 | J7: — | K7: ponytail | L7: Non fait
A8: P6-07 | B8: 54 | C8: Sécurité : RBAC, TLS, scans | D8: Rôles, chiffrement en transit et scan automatique des dépendances/secrets. | E8: src/adp/api/rbac.py (rôles viewer/steward/admin), reverse proxy Caddy/Traefik TLS en compose, CI : pip-audit + gitleaks. | F8: Sécurité de bout en bout. Compétence : DevSecOps. | G8: `pytest tests/api/test_rbac.py` : viewer ne peut pas approuver un mapping ; CI de sécurité verte ; HTTPS actif en local. | H8: Sonnet | I8: P5-03 | J8: — | K8: ponytail | L8: Non fait
A9: P6-08 | B9: 55 | C9: (Stretch) Hot path en Rust via PyO3 | D9: Réécrire le calcul de similarité du diff en Rust pour mesurer le gain. | E9: rust/adp_core/ (maturin, PyO3) exposant similarity_matrix, intégration optionnelle avec fallback Python. | F9: Montre la maîtrise Rust/Python pour les chemins critiques. Compétence : Rust, performance. À faire seulement si H-03 confirme. | G9: `maturin develop && pytest tests/schema/test_rust_parity.py` : résultats identiques au Python ; benchmark ≥ x fois plus rapide. | H9: Opus | I9: P2-03, P6-05 | J9: H-03 | K9: ponytail | L9: Non fait
A10: P6-09 | B10: 56 | C10: Benchmarks & rapport de performance | D10: Mesurer débit, latence et gains de l'optimisation. | E10: scripts/bench.py, docs/perf/report.md (méthodo, matériel, résultats, limites). | F10: Chiffres vérifiables pour CV et entretiens. Compétence : benchmarking rigoureux. | G10: `make bench` régénère le rapport ; chaque chiffre du rapport est reproductible (commande indiquée). | H10: Sonnet | I10: P6-06 | J10: H-11 | K10: ponytail | L10: Non fait

Sheet P7_Portfolio_CV
A1: ID | B1: Ordre | C1: Tâche | D1: Objectif | E1: Code à produire | F1: Explication & compétence CV | G1: Test de validation | H1: Modèle | I1: Dépendances | J1: Hypothèse | K1: Skills / plugins | L1: Statut | M1: Preuve / notes Claude
A2: P7-01 | B2: 57 | C2: README professionnel | D2: Page d'accueil GitHub : problème, architecture, démo, quickstart. | E2: README.md (badges, diagramme, GIF, quickstart en 5 commandes, structure, roadmap). | F2: Première impression du recruteur. Compétence : communication technique. | G2: Un lecteur neuf exécute le quickstart sans aide et obtient la démo ; liens vérifiés (`lychee`). | H2: Haiku | I2: P6-09 | J2: — | K2: ponytail | L2: Non fait
A3: P7-02 | B3: 58 | C3: Documentation (MkDocs) | D3: Site de doc : architecture, guides, API, ADR. | E3: mkdocs.yml, docs/ complété, déploiement GitHub Pages via workflow. | F3: Prouve la maintenabilité. Compétence : documentation. | G3: `mkdocs build --strict` sans avertissement ; site publié. | H3: Haiku | I3: P7-01 | J3: — | K3: ponytail | L3: Non fait
A4: P7-03 | B4: 59 | C4: Démo reproductible de bout en bout | D4: Une commande rejoue le scénario dérive v1→v3 avec auto-mapping, quarantaine et dashboard. | E4: Makefile `demo`, scripts/demo.py, jeux seedés, script de reset. | F4: Montre la valeur en 3 minutes. Compétence : storytelling technique. | G4: `make reset demo` deux fois → même résultat ; checklist de la démo cochée. | H4: Sonnet | I4: P7-02 | J4: — | K4: ponytail | L4: Non fait
A5: P7-04 | B5: 60 | C5: GIF/vidéo de démonstration | D5: Capsule visuelle de 60-90 s pour README et LinkedIn. | E5: docs/media/demo.gif + demo.mp4 (script de capture reproductible), sous-titres. | F5: Visibilité du projet. Compétence : présentation. | G5: Fichiers < 10 Mo, lisibles, scénario conforme à P7-03 (validation visuelle utilisateur). | H5: Sonnet | I5: P7-03 | J5: H-12 | K5: motion | L5: Non fait
A6: P7-05 | B6: 61 | C6: Étude de cas BA / BIA | D6: Document de 4-6 pages : problème métier, parties prenantes, exigences, KPI, ROI estimé, risques et impacts. | E6: docs/case-study.md (canevas BABOK-like : contexte, besoins, user stories, matrice RACI, KPIs, analyse d'impact, risques). | F6: Distingue un profil data de bout en bout d'un simple développeur. Compétence : analyse métier, BIA. | G6: Relecture : chaque KPI est lié à une mesure du projet ; chaque risque a une mitigation ; validation utilisateur. | H6: Opus | I6: P7-03 | J6: H-01, H-05 | K6: — | L6: Non fait
A7: P7-06 | B7: 62 | C7: Contenus CV & LinkedIn | D7: Bullet points orientés résultats, résumé de profil et mapping des compétences. | E7: docs/career/cv-bullets.md (versions FR/EN, format action-métrique-résultat), linkedin.md, skills-matrix.md. | F7: Convertit le projet en arguments de candidature. Compétence : positionnement. | G7: Chaque chiffre cité dans un bullet pointe vers une preuve du repo ; validation utilisateur. | H7: Sonnet | I7: P7-05, P6-09 | J7: H-05 | K7: portfolio-writer | L7: Non fait
A8: P7-07 | B8: 63 | C8: Cartographie compétences ↔ postes visés | D8: Aligner le projet sur les offres/programmes ciblés. | E8: docs/career/target-roles.md (offres cibles, compétences exigées, preuves dans le projet, écarts à combler). | F8: Rend la candidature ciblée. Compétence : stratégie de carrière. | G8: Tableau complet pour ≥ 5 offres réelles fournies par l'utilisateur ; chaque écart a un plan. | H8: Sonnet | I8: P7-06 | J8: H-05 | K8: portfolio-writer | L8: Non fait
A9: P7-08 | B9: 64 | C9: Release v1.0 | D9: Finaliser et publier. | E9: CHANGELOG.md, tag v1.0.0, GitHub release, topics et description du repo, passage en public si décidé. | F9: Clôture professionnelle. Compétence : release management. | G9: CI verte sur main, tag poussé, release visible ; décision de visibilité confirmée par l'utilisateur. | H9: Haiku | I9: P7-07 | J9: H-13 | K9: ponytail | L9: Non fait

Sheet Hypotheses
A1: ID | B1: Tâches concernées | C1: Question / zone d'ambiguïté | D1: Hypothèse de travail retenue | E1: Impact si l'hypothèse est fausse | F1: Précision à demander à l'utilisateur | G1: Statut | H1: Décision / réponse | I1: Date
A2: H-01 | B2: P1-01, P1-03, P1-07, P3-01, P5-01, P7-05 | C2: Quelles sources de données réelles utiliser pour le projet (APIs, fichiers, bases) et sur quel domaine métier ? | D2: Jeux publics : une API ouverte (ex. World Bank) + CSV/Excel d'open data marocain + versions dérivantes générées par le simulateur. Domaine : indicateurs socio-économiques. | E2: Modèle canonique, contrats Gold et étude de cas à refaire. | F2: Fournir 2-3 sources réelles prioritaires et le domaine (HCP, GED, autre) ; données sensibles à exclure. | G2: Ouverte
A3: H-02 | B3: P2-04, P3-04, P4-04, P6-03 | C3: Quels seuils de décision automatique vs revue humaine (confiance mapping, taux de quarantaine, budget de retries) ? | D3: Auto-apply ≥ 0.90 ; revue entre 0.60 et 0.90 ; rejet < 0.60 ; quarantaine ligne si < 5 % invalides, lot si ≥ 20 % ; 3 retries max. | E3: Trop de revues manuelles ou, pire, de mauvaises corrections automatiques. | F3: Valider ou ajuster ces seuils après l'évaluation P3-09. | G3: Ouverte
A4: H-03 | B4: P0-07, P2-03, P6-08 | C4: Faut-il intégrer Rust et/ou Go (mentionnés dans le schéma) ou rester 100 % Python ? | D4: MVP 100 % Python. Rust en option (P6-08) uniquement pour le calcul de similarité ; Go non retenu pour le MVP. | E4: Si exigé : planning de P6 à rallonger ; sinon P6-08 est supprimée. | F4: Dire si Rust/Go sont des compétences à démontrer explicitement pour les postes visés. | G4: Ouverte
A5: H-04 | B5: P0-02, P0-07, P2-02 | C5: Magasin de métadonnées : SQLite ou PostgreSQL ? | D5: PostgreSQL dès le début (via Docker) pour la concurrence et la crédibilité ; SQLite uniquement pour les tests unitaires. | E5: Migration plus tardive plus coûteuse. | F5: Confirmer que Docker est disponible et acceptable sur la machine de démonstration. | G5: Ouverte
A6: H-05 | B6: P5-01, P7-05, P7-06, P7-07 | C6: Que vise précisément la candidature (« grade » : programme graduate, grade/poste précis, concours) et pour quel pays/employeur ? | D6: Postes data engineer / analytics engineer junior-confirmé et programmes graduate data, France/Maroc/Europe. | E6: Cartographie compétences et ton du CV mal ciblés. | F6: Préciser le type de poste, le pays, la langue du CV et 5 offres cibles. | G6: Ouverte
A7: H-06 | B7: P0-01 | C7: Versions et outils : Python 3.12 + uv, ruff, mypy ? | D7: Python 3.12, uv comme gestionnaire, ruff + mypy, pytest. | E7: Faible : réversible. | F7: Signaler toute contrainte (conda, version imposée). | G7: Ouverte
A8: H-07 | B8: P0-06 | C8: Le dossier graphify-out/ doit-il être commité ? | D8: Commiter GRAPH_REPORT.md uniquement ; graph.json et cache ignorés. | E8: Taille du repo ou perte de contexte pour de nouvelles sessions. | F8: Confirmer la préférence. | G8: Ouverte
A9: H-08 | B9: P1-09 | C9: Orchestrateur : Dagster (schéma) ou Prefect/Airflow ? | D9: Dagster, conforme au schéma d'architecture (assets + lignage natif). | E9: Réécriture des P1-09, P2-06, P4-07. | F9: Confirmer. | G9: Ouverte
A10: H-09 | B10: P3-03, P3-09, P6-02 | C10: Fournisseur LLM, budget et exigences de confidentialité pour le mapping et la RCA ? | D10: API Claude via clé personnelle, modèle Haiku/Sonnet selon la tâche, plafond de dépense configurable ; aucune donnée sensible envoyée (seuls noms de colonnes + échantillons anonymisés). Fallback local sans LLM. | E10: Coût, confidentialité, reproductibilité de la démo. | F10: Fournir une clé API de test (jamais commitée) et un plafond de budget ; confirmer l'interdiction d'envoyer des valeurs réelles. | G10: Ouverte
A11: H-10 | B11: P5-05, P5-06, P5-07 | C11: Stack et identité visuelle de l'interface ? | D11: React + Vite + TS + Tailwind ; thème sobre clair/sombre ; skill ui-ux-pro-max pour le design system ; 'motion skills' = Framer Motion + règles reduced-motion. | E11: Refonte du front si stack différente. | F11: Confirmer la stack et préciser ce que recouvre exactement « motion skills agent ». | G11: Ouverte
A12: H-11 | B12: P6-05, P6-09 | C12: Quelle cible de gain de performance valide l'auto-optimisation ? | D12: Réduction ≥ 30 % de la latence p95 sur la requête la plus fréquente, mesurée sur jeu de 1 M lignes. | E12: Objectif trop ambitieux ou trivial. | F12: Valider la cible et la taille du jeu de test. | G12: Ouverte
A13: H-12 | B13: P7-04 | C13: Format et outil pour la vidéo de démo ? | D13: GIF + MP4 capturés depuis le navigateur, sous-titres FR/EN. | E13: Faible. | F13: Indiquer les canaux visés (LinkedIn, GitHub, entretien). | G13: Ouverte
A14: H-13 | B14: P7-08 | C14: Le dépôt doit-il rester privé ou devenir public ? | D14: Privé pendant le développement ; passage en public à la release v1.0 après relecture sécurité. | E14: Fuite de données ou secrets si publié trop tôt ; invisibilité si jamais publié. | F14: Décision explicite de l'utilisateur avant la release. | G14: Ouverte

Sheet Legende
A1: Cycle de vie d'une tâche
A2: Non fait | B2: Pas commencée.
A3: En cours | B3: Claude travaille dessus (une seule tâche En cours à la fois).
A4: À valider | B4: Code écrit, tests de la colonne G passés, preuve notée. En attente de la gate de phase.
A5: Validé | B5: Posé uniquement par la commande de validation de phase, après accord explicite de l'utilisateur.
A7: Choix du modèle
A8: Opus | B8: Conception, algorithmes critiques, sécurité, décisions d'architecture.
A9: Sonnet | B9: Implémentation standard, API, tests, intégration.
A10: Haiku | B10: Échafaudage, documentation, configuration, tâches mécaniques.
A12: Règles
A13: Source de vérité | B13: Ce classeur. Ne pas l'éditer à la main pendant qu'une session Claude tourne : utiliser scripts/backlog.py.
A14: Ordre d'exécution | B14: Feuille Ordre_Execution. Les dépendances (colonne I) doivent être À valider ou Validé avant de démarrer.
A15: Hypothèses | B15: Si une tâche est ambiguë : noter la référence H-xx, travailler sur l'hypothèse retenue, et la remonter à la gate de phase.
A16: Gate de phase | B16: Fin de phase : Claude s'arrête, présente le bilan, attend « validé » de l'utilisateur.
